2023-10-12 21:12:22,247 - INFO - Bot démarré
2023-10-12 21:12:22,280 - INFO - Scheduler started
2023-10-12 21:12:22,851 - WARNING - Utilisateur 1709873116 est dans la liste des bannis.
2023-10-12 21:12:22,860 - WARNING - Utilisateur 1709873116 est banni.
2023-10-12 21:13:36,936 - INFO - Received signal 2 (SIGINT), stopping...
2023-10-12 21:13:36,936 - INFO - Scheduler has been shut down
2023-10-12 21:13:43,251 - WARNING - Exiting immediately!
2023-10-12 21:13:53,097 - INFO - Bot démarré
2023-10-12 21:13:53,102 - INFO - Scheduler started
2023-10-12 21:13:56,901 - WARNING - Utilisateur 1709873116 est dans la liste des bannis.
2023-10-12 21:13:56,905 - WARNING - Utilisateur 1709873116 est banni.
2023-10-12 21:14:00,236 - INFO - Received signal 2 (SIGINT), stopping...
2023-10-12 21:14:00,237 - INFO - Scheduler has been shut down
2023-10-12 21:14:01,118 - WARNING - Exiting immediately!
2023-10-12 21:14:26,571 - INFO - Bot démarré
2023-10-12 21:14:26,576 - INFO - Scheduler started
2023-10-12 23:41:45,206 - WARNING - Retrying (Retry(total=2, connect=None, read=None, redirect=None)) after connection broken by 'NewConnectionError('<telegram.vendor.ptb_urllib3.urllib3.connection.VerifiedHTTPSConnection object at 0x000001B8FCB14F40>: Failed to establish a new connection: [Errno 11001] getaddrinfo failed')': /bot6140284584:AAF8gviWzKMkHEn5TktrVMral7PPMW7uxXk/getUpdates
2023-10-12 23:41:45,235 - WARNING - Retrying (Retry(total=1, connect=None, read=None, redirect=None)) after connection broken by 'NewConnectionError('<telegram.vendor.ptb_urllib3.urllib3.connection.VerifiedHTTPSConnection object at 0x000001B8FCB14FD0>: Failed to establish a new connection: [Errno 11001] getaddrinfo failed')': /bot6140284584:AAF8gviWzKMkHEn5TktrVMral7PPMW7uxXk/getUpdates
2023-10-12 23:41:45,306 - WARNING - Retrying (Retry(total=0, connect=None, read=None, redirect=None)) after connection broken by 'NewConnectionError('<telegram.vendor.ptb_urllib3.urllib3.connection.VerifiedHTTPSConnection object at 0x000001B8FCB15180>: Failed to establish a new connection: [Errno 11001] getaddrinfo failed')': /bot6140284584:AAF8gviWzKMkHEn5TktrVMral7PPMW7uxXk/getUpdates
2023-10-12 23:41:45,768 - ERROR - Error while getting Updates: urllib3 HTTPError HTTPSConnectionPool(host='api.telegram.org', port=443): Max retries exceeded with url: /bot6140284584:AAF8gviWzKMkHEn5TktrVMral7PPMW7uxXk/getUpdates (Caused by NewConnectionError('<telegram.vendor.ptb_urllib3.urllib3.connection.VerifiedHTTPSConnection object at 0x000001B8FCB15300>: Failed to establish a new connection: [Errno 11001] getaddrinfo failed'))
2023-10-12 23:41:45,774 - ERROR - No error handlers are registered, logging exception.
Traceback (most recent call last):
  File "C:\Users\gaylo\AppData\Local\Packages\PythonSoftwareFoundation.Python.3.10_qbz5n2kfra8p0\LocalCache\local-packages\Python310\site-packages\telegram\vendor\ptb_urllib3\urllib3\connection.py", line 140, in _new_conn
    conn = connection.create_connection(
  File "C:\Users\gaylo\AppData\Local\Packages\PythonSoftwareFoundation.Python.3.10_qbz5n2kfra8p0\LocalCache\local-packages\Python310\site-packages\telegram\vendor\ptb_urllib3\urllib3\util\connection.py", line 60, in create_connection
    for res in socket.getaddrinfo(host, port, family, socket.SOCK_STREAM):
  File "C:\Program Files\WindowsApps\PythonSoftwareFoundation.Python.3.10_3.10.3056.0_x64__qbz5n2kfra8p0\lib\socket.py", line 955, in getaddrinfo
    for res in _socket.getaddrinfo(host, port, family, type, proto, flags):
socket.gaierror: [Errno 11001] getaddrinfo failed

During handling of the above exception, another exception occurred:

Traceback (most recent call last):
  File "C:\Users\gaylo\AppData\Local\Packages\PythonSoftwareFoundation.Python.3.10_qbz5n2kfra8p0\LocalCache\local-packages\Python310\site-packages\telegram\vendor\ptb_urllib3\urllib3\connectionpool.py", line 614, in urlopen
    httplib_response = self._make_request(conn, method, url,
  File "C:\Users\gaylo\AppData\Local\Packages\PythonSoftwareFoundation.Python.3.10_qbz5n2kfra8p0\LocalCache\local-packages\Python310\site-packages\telegram\vendor\ptb_urllib3\urllib3\connectionpool.py", line 360, in _make_request
    self._validate_conn(conn)
  File "C:\Users\gaylo\AppData\Local\Packages\PythonSoftwareFoundation.Python.3.10_qbz5n2kfra8p0\LocalCache\local-packages\Python310\site-packages\telegram\vendor\ptb_urllib3\urllib3\connectionpool.py", line 857, in _validate_conn
    super(HTTPSConnectionPool, self)._validate_conn(conn)
  File "C:\Users\gaylo\AppData\Local\Packages\PythonSoftwareFoundation.Python.3.10_qbz5n2kfra8p0\LocalCache\local-packages\Python310\site-packages\telegram\vendor\ptb_urllib3\urllib3\connectionpool.py", line 289, in _validate_conn
    conn.connect()
  File "C:\Users\gaylo\AppData\Local\Packages\PythonSoftwareFoundation.Python.3.10_qbz5n2kfra8p0\LocalCache\local-packages\Python310\site-packages\telegram\vendor\ptb_urllib3\urllib3\connection.py", line 284, in connect
    conn = self._new_conn()
  File "C:\Users\gaylo\AppData\Local\Packages\PythonSoftwareFoundation.Python.3.10_qbz5n2kfra8p0\LocalCache\local-packages\Python310\site-packages\telegram\vendor\ptb_urllib3\urllib3\connection.py", line 149, in _new_conn
    raise NewConnectionError(
telegram.vendor.ptb_urllib3.urllib3.exceptions.NewConnectionError: <telegram.vendor.ptb_urllib3.urllib3.connection.VerifiedHTTPSConnection object at 0x000001B8FCB15300>: Failed to establish a new connection: [Errno 11001] getaddrinfo failed

During handling of the above exception, another exception occurred:

Traceback (most recent call last):
  File "C:\Users\gaylo\AppData\Local\Packages\PythonSoftwareFoundation.Python.3.10_qbz5n2kfra8p0\LocalCache\local-packages\Python310\site-packages\telegram\utils\request.py", line 259, in _request_wrapper
    resp = self._con_pool.request(*args, **kwargs)
  File "C:\Users\gaylo\AppData\Local\Packages\PythonSoftwareFoundation.Python.3.10_qbz5n2kfra8p0\LocalCache\local-packages\Python310\site-packages\telegram\vendor\ptb_urllib3\urllib3\request.py", line 68, in request
    return self.request_encode_body(method, url, fields=fields,
  File "C:\Users\gaylo\AppData\Local\Packages\PythonSoftwareFoundation.Python.3.10_qbz5n2kfra8p0\LocalCache\local-packages\Python310\site-packages\telegram\vendor\ptb_urllib3\urllib3\request.py", line 148, in request_encode_body
    return self.urlopen(method, url, **extra_kw)
  File "C:\Users\gaylo\AppData\Local\Packages\PythonSoftwareFoundation.Python.3.10_qbz5n2kfra8p0\LocalCache\local-packages\Python310\site-packages\telegram\vendor\ptb_urllib3\urllib3\poolmanager.py", line 244, in urlopen
    response = conn.urlopen(method, u.request_uri, **kw)
  File "C:\Users\gaylo\AppData\Local\Packages\PythonSoftwareFoundation.Python.3.10_qbz5n2kfra8p0\LocalCache\local-packages\Python310\site-packages\telegram\vendor\ptb_urllib3\urllib3\connectionpool.py", line 691, in urlopen
    return self.urlopen(method, url, body, headers, retries,
  File "C:\Users\gaylo\AppData\Local\Packages\PythonSoftwareFoundation.Python.3.10_qbz5n2kfra8p0\LocalCache\local-packages\Python310\site-packages\telegram\vendor\ptb_urllib3\urllib3\connectionpool.py", line 691, in urlopen
    return self.urlopen(method, url, body, headers, retries,
  File "C:\Users\gaylo\AppData\Local\Packages\PythonSoftwareFoundation.Python.3.10_qbz5n2kfra8p0\LocalCache\local-packages\Python310\site-packages\telegram\vendor\ptb_urllib3\urllib3\connectionpool.py", line 691, in urlopen
    return self.urlopen(method, url, body, headers, retries,
  File "C:\Users\gaylo\AppData\Local\Packages\PythonSoftwareFoundation.Python.3.10_qbz5n2kfra8p0\LocalCache\local-packages\Python310\site-packages\telegram\vendor\ptb_urllib3\urllib3\connectionpool.py", line 665, in urlopen
    retries = retries.increment(method, url, error=e, _pool=self,
  File "C:\Users\gaylo\AppData\Local\Packages\PythonSoftwareFoundation.Python.3.10_qbz5n2kfra8p0\LocalCache\local-packages\Python310\site-packages\telegram\vendor\ptb_urllib3\urllib3\util\retry.py", line 376, in increment
    raise MaxRetryError(_pool, url, error or ResponseError(cause))
telegram.vendor.ptb_urllib3.urllib3.exceptions.MaxRetryError: HTTPSConnectionPool(host='api.telegram.org', port=443): Max retries exceeded with url: /bot6140284584:AAF8gviWzKMkHEn5TktrVMral7PPMW7uxXk/getUpdates (Caused by NewConnectionError('<telegram.vendor.ptb_urllib3.urllib3.connection.VerifiedHTTPSConnection object at 0x000001B8FCB15300>: Failed to establish a new connection: [Errno 11001] getaddrinfo failed'))

The above exception was the direct cause of the following exception:

Traceback (most recent call last):
  File "C:\Users\gaylo\AppData\Local\Packages\PythonSoftwareFoundation.Python.3.10_qbz5n2kfra8p0\LocalCache\local-packages\Python310\site-packages\telegram\ext\updater.py", line 651, in _network_loop_retry
    if not action_cb():
  File "C:\Users\gaylo\AppData\Local\Packages\PythonSoftwareFoundation.Python.3.10_qbz5n2kfra8p0\LocalCache\local-packages\Python310\site-packages\telegram\ext\updater.py", line 602, in polling_action_cb
    updates = self.bot.get_updates(
  File "C:\Users\gaylo\AppData\Local\Packages\PythonSoftwareFoundation.Python.3.10_qbz5n2kfra8p0\LocalCache\local-packages\Python310\site-packages\telegram\ext\extbot.py", line 226, in get_updates
    updates = super().get_updates(
  File "C:\Users\gaylo\AppData\Local\Packages\PythonSoftwareFoundation.Python.3.10_qbz5n2kfra8p0\LocalCache\local-packages\Python310\site-packages\telegram\bot.py", line 133, in decorator
    result = func(*args, **kwargs)
  File "C:\Users\gaylo\AppData\Local\Packages\PythonSoftwareFoundation.Python.3.10_qbz5n2kfra8p0\LocalCache\local-packages\Python310\site-packages\telegram\bot.py", line 3057, in get_updates
    self._post(
  File "C:\Users\gaylo\AppData\Local\Packages\PythonSoftwareFoundation.Python.3.10_qbz5n2kfra8p0\LocalCache\local-packages\Python310\site-packages\telegram\bot.py", line 298, in _post
    return self.request.post(
  File "C:\Users\gaylo\AppData\Local\Packages\PythonSoftwareFoundation.Python.3.10_qbz5n2kfra8p0\LocalCache\local-packages\Python310\site-packages\telegram\utils\request.py", line 361, in post
    result = self._request_wrapper(
  File "C:\Users\gaylo\AppData\Local\Packages\PythonSoftwareFoundation.Python.3.10_qbz5n2kfra8p0\LocalCache\local-packages\Python310\site-packages\telegram\utils\request.py", line 265, in _request_wrapper
    raise NetworkError(f'urllib3 HTTPError {error}') from error
telegram.error.NetworkError: urllib3 HTTPError HTTPSConnectionPool(host='api.telegram.org', port=443): Max retries exceeded with url: /bot6140284584:AAF8gviWzKMkHEn5TktrVMral7PPMW7uxXk/getUpdates (Caused by NewConnectionError('<telegram.vendor.ptb_urllib3.urllib3.connection.VerifiedHTTPSConnection object at 0x000001B8FCB15300>: Failed to establish a new connection: [Errno 11001] getaddrinfo failed'))
2023-10-12 23:41:46,897 - WARNING - Retrying (Retry(total=2, connect=None, read=None, redirect=None)) after connection broken by 'NewConnectionError('<telegram.vendor.ptb_urllib3.urllib3.connection.VerifiedHTTPSConnection object at 0x000001B8FCB15840>: Failed to establish a new connection: [Errno 11001] getaddrinfo failed')': /bot6140284584:AAF8gviWzKMkHEn5TktrVMral7PPMW7uxXk/getUpdates
2023-10-12 23:41:47,084 - WARNING - Retrying (Retry(total=1, connect=None, read=None, redirect=None)) after connection broken by 'NewConnectionError('<telegram.vendor.ptb_urllib3.urllib3.connection.VerifiedHTTPSConnection object at 0x000001B8FCB15810>: Failed to establish a new connection: [Errno 11001] getaddrinfo failed')': /bot6140284584:AAF8gviWzKMkHEn5TktrVMral7PPMW7uxXk/getUpdates
2023-10-12 23:41:47,086 - WARNING - Retrying (Retry(total=0, connect=None, read=None, redirect=None)) after connection broken by 'NewConnectionError('<telegram.vendor.ptb_urllib3.urllib3.connection.VerifiedHTTPSConnection object at 0x000001B8FCB15A20>: Failed to establish a new connection: [Errno 11001] getaddrinfo failed')': /bot6140284584:AAF8gviWzKMkHEn5TktrVMral7PPMW7uxXk/getUpdates
2023-10-12 23:41:47,089 - ERROR - Error while getting Updates: urllib3 HTTPError HTTPSConnectionPool(host='api.telegram.org', port=443): Max retries exceeded with url: /bot6140284584:AAF8gviWzKMkHEn5TktrVMral7PPMW7uxXk/getUpdates (Caused by NewConnectionError('<telegram.vendor.ptb_urllib3.urllib3.connection.VerifiedHTTPSConnection object at 0x000001B8FCB15B70>: Failed to establish a new connection: [Errno 11001] getaddrinfo failed'))
2023-10-12 23:41:47,091 - ERROR - No error handlers are registered, logging exception.
Traceback (most recent call last):
  File "C:\Users\gaylo\AppData\Local\Packages\PythonSoftwareFoundation.Python.3.10_qbz5n2kfra8p0\LocalCache\local-packages\Python310\site-packages\telegram\vendor\ptb_urllib3\urllib3\connection.py", line 140, in _new_conn
    conn = connection.create_connection(
  File "C:\Users\gaylo\AppData\Local\Packages\PythonSoftwareFoundation.Python.3.10_qbz5n2kfra8p0\LocalCache\local-packages\Python310\site-packages\telegram\vendor\ptb_urllib3\urllib3\util\connection.py", line 60, in create_connection
    for res in socket.getaddrinfo(host, port, family, socket.SOCK_STREAM):
  File "C:\Program Files\WindowsApps\PythonSoftwareFoundation.Python.3.10_3.10.3056.0_x64__qbz5n2kfra8p0\lib\socket.py", line 955, in getaddrinfo
    for res in _socket.getaddrinfo(host, port, family, type, proto, flags):
socket.gaierror: [Errno 11001] getaddrinfo failed

During handling of the above exception, another exception occurred:

Traceback (most recent call last):
  File "C:\Users\gaylo\AppData\Local\Packages\PythonSoftwareFoundation.Python.3.10_qbz5n2kfra8p0\LocalCache\local-packages\Python310\site-packages\telegram\vendor\ptb_urllib3\urllib3\connectionpool.py", line 614, in urlopen
    httplib_response = self._make_request(conn, method, url,
  File "C:\Users\gaylo\AppData\Local\Packages\PythonSoftwareFoundation.Python.3.10_qbz5n2kfra8p0\LocalCache\local-packages\Python310\site-packages\telegram\vendor\ptb_urllib3\urllib3\connectionpool.py", line 360, in _make_request
    self._validate_conn(conn)
  File "C:\Users\gaylo\AppData\Local\Packages\PythonSoftwareFoundation.Python.3.10_qbz5n2kfra8p0\LocalCache\local-packages\Python310\site-packages\telegram\vendor\ptb_urllib3\urllib3\connectionpool.py", line 857, in _validate_conn
    super(HTTPSConnectionPool, self)._validate_conn(conn)
  File "C:\Users\gaylo\AppData\Local\Packages\PythonSoftwareFoundation.Python.3.10_qbz5n2kfra8p0\LocalCache\local-packages\Python310\site-packages\telegram\vendor\ptb_urllib3\urllib3\connectionpool.py", line 289, in _validate_conn
    conn.connect()
  File "C:\Users\gaylo\AppData\Local\Packages\PythonSoftwareFoundation.Python.3.10_qbz5n2kfra8p0\LocalCache\local-packages\Python310\site-packages\telegram\vendor\ptb_urllib3\urllib3\connection.py", line 284, in connect
    conn = self._new_conn()
  File "C:\Users\gaylo\AppData\Local\Packages\PythonSoftwareFoundation.Python.3.10_qbz5n2kfra8p0\LocalCache\local-packages\Python310\site-packages\telegram\vendor\ptb_urllib3\urllib3\connection.py", line 149, in _new_conn
    raise NewConnectionError(
telegram.vendor.ptb_urllib3.urllib3.exceptions.NewConnectionError: <telegram.vendor.ptb_urllib3.urllib3.connection.VerifiedHTTPSConnection object at 0x000001B8FCB15B70>: Failed to establish a new connection: [Errno 11001] getaddrinfo failed

During handling of the above exception, another exception occurred:

Traceback (most recent call last):
  File "C:\Users\gaylo\AppData\Local\Packages\PythonSoftwareFoundation.Python.3.10_qbz5n2kfra8p0\LocalCache\local-packages\Python310\site-packages\telegram\utils\request.py", line 259, in _request_wrapper
    resp = self._con_pool.request(*args, **kwargs)
  File "C:\Users\gaylo\AppData\Local\Packages\PythonSoftwareFoundation.Python.3.10_qbz5n2kfra8p0\LocalCache\local-packages\Python310\site-packages\telegram\vendor\ptb_urllib3\urllib3\request.py", line 68, in request
    return self.request_encode_body(method, url, fields=fields,
  File "C:\Users\gaylo\AppData\Local\Packages\PythonSoftwareFoundation.Python.3.10_qbz5n2kfra8p0\LocalCache\local-packages\Python310\site-packages\telegram\vendor\ptb_urllib3\urllib3\request.py", line 148, in request_encode_body
    return self.urlopen(method, url, **extra_kw)
  File "C:\Users\gaylo\AppData\Local\Packages\PythonSoftwareFoundation.Python.3.10_qbz5n2kfra8p0\LocalCache\local-packages\Python310\site-packages\telegram\vendor\ptb_urllib3\urllib3\poolmanager.py", line 244, in urlopen
    response = conn.urlopen(method, u.request_uri, **kw)
  File "C:\Users\gaylo\AppData\Local\Packages\PythonSoftwareFoundation.Python.3.10_qbz5n2kfra8p0\LocalCache\local-packages\Python310\site-packages\telegram\vendor\ptb_urllib3\urllib3\connectionpool.py", line 691, in urlopen
    return self.urlopen(method, url, body, headers, retries,
  File "C:\Users\gaylo\AppData\Local\Packages\PythonSoftwareFoundation.Python.3.10_qbz5n2kfra8p0\LocalCache\local-packages\Python310\site-packages\telegram\vendor\ptb_urllib3\urllib3\connectionpool.py", line 691, in urlopen
    return self.urlopen(method, url, body, headers, retries,
  File "C:\Users\gaylo\AppData\Local\Packages\PythonSoftwareFoundation.Python.3.10_qbz5n2kfra8p0\LocalCache\local-packages\Python310\site-packages\telegram\vendor\ptb_urllib3\urllib3\connectionpool.py", line 691, in urlopen
    return self.urlopen(method, url, body, headers, retries,
  File "C:\Users\gaylo\AppData\Local\Packages\PythonSoftwareFoundation.Python.3.10_qbz5n2kfra8p0\LocalCache\local-packages\Python310\site-packages\telegram\vendor\ptb_urllib3\urllib3\connectionpool.py", line 665, in urlopen
    retries = retries.increment(method, url, error=e, _pool=self,
  File "C:\Users\gaylo\AppData\Local\Packages\PythonSoftwareFoundation.Python.3.10_qbz5n2kfra8p0\LocalCache\local-packages\Python310\site-packages\telegram\vendor\ptb_urllib3\urllib3\util\retry.py", line 376, in increment
    raise MaxRetryError(_pool, url, error or ResponseError(cause))
telegram.vendor.ptb_urllib3.urllib3.exceptions.MaxRetryError: HTTPSConnectionPool(host='api.telegram.org', port=443): Max retries exceeded with url: /bot6140284584:AAF8gviWzKMkHEn5TktrVMral7PPMW7uxXk/getUpdates (Caused by NewConnectionError('<telegram.vendor.ptb_urllib3.urllib3.connection.VerifiedHTTPSConnection object at 0x000001B8FCB15B70>: Failed to establish a new connection: [Errno 11001] getaddrinfo failed'))

The above exception was the direct cause of the following exception:

Traceback (most recent call last):
  File "C:\Users\gaylo\AppData\Local\Packages\PythonSoftwareFoundation.Python.3.10_qbz5n2kfra8p0\LocalCache\local-packages\Python310\site-packages\telegram\ext\updater.py", line 651, in _network_loop_retry
    if not action_cb():
  File "C:\Users\gaylo\AppData\Local\Packages\PythonSoftwareFoundation.Python.3.10_qbz5n2kfra8p0\LocalCache\local-packages\Python310\site-packages\telegram\ext\updater.py", line 602, in polling_action_cb
    updates = self.bot.get_updates(
  File "C:\Users\gaylo\AppData\Local\Packages\PythonSoftwareFoundation.Python.3.10_qbz5n2kfra8p0\LocalCache\local-packages\Python310\site-packages\telegram\ext\extbot.py", line 226, in get_updates
    updates = super().get_updates(
  File "C:\Users\gaylo\AppData\Local\Packages\PythonSoftwareFoundation.Python.3.10_qbz5n2kfra8p0\LocalCache\local-packages\Python310\site-packages\telegram\bot.py", line 133, in decorator
    result = func(*args, **kwargs)
  File "C:\Users\gaylo\AppData\Local\Packages\PythonSoftwareFoundation.Python.3.10_qbz5n2kfra8p0\LocalCache\local-packages\Python310\site-packages\telegram\bot.py", line 3057, in get_updates
    self._post(
  File "C:\Users\gaylo\AppData\Local\Packages\PythonSoftwareFoundation.Python.3.10_qbz5n2kfra8p0\LocalCache\local-packages\Python310\site-packages\telegram\bot.py", line 298, in _post
    return self.request.post(
  File "C:\Users\gaylo\AppData\Local\Packages\PythonSoftwareFoundation.Python.3.10_qbz5n2kfra8p0\LocalCache\local-packages\Python310\site-packages\telegram\utils\request.py", line 361, in post
    result = self._request_wrapper(
  File "C:\Users\gaylo\AppData\Local\Packages\PythonSoftwareFoundation.Python.3.10_qbz5n2kfra8p0\LocalCache\local-packages\Python310\site-packages\telegram\utils\request.py", line 265, in _request_wrapper
    raise NetworkError(f'urllib3 HTTPError {error}') from error
telegram.error.NetworkError: urllib3 HTTPError HTTPSConnectionPool(host='api.telegram.org', port=443): Max retries exceeded with url: /bot6140284584:AAF8gviWzKMkHEn5TktrVMral7PPMW7uxXk/getUpdates (Caused by NewConnectionError('<telegram.vendor.ptb_urllib3.urllib3.connection.VerifiedHTTPSConnection object at 0x000001B8FCB15B70>: Failed to establish a new connection: [Errno 11001] getaddrinfo failed'))
2023-10-12 23:41:53,745 - WARNING - Retrying (Retry(total=2, connect=None, read=None, redirect=None)) after connection broken by 'ConnectTimeoutError(<telegram.vendor.ptb_urllib3.urllib3.connection.VerifiedHTTPSConnection object at 0x000001B8FCB154B0>, 'Connection to api.telegram.org timed out. (connect timeout=5.0)')': /bot6140284584:AAF8gviWzKMkHEn5TktrVMral7PPMW7uxXk/getUpdates
2023-10-13 00:06:16,604 - INFO - Received signal 2 (SIGINT), stopping...
2023-10-13 00:06:16,633 - INFO - Scheduler has been shut down
2023-10-13 00:06:16,773 - WARNING - Exiting immediately!
2023-10-13 00:06:22,658 - INFO - Bot démarré
2023-10-13 00:06:22,663 - INFO - Scheduler started
2023-10-13 00:06:26,109 - INFO - Utilisateur 1709873116 n'est pas dans la liste des bannis.
2023-10-13 00:06:26,110 - INFO - Utilisateur 1709873116 autorisé.
2023-10-13 00:06:30,144 - INFO - Received signal 2 (SIGINT), stopping...
2023-10-13 00:06:30,144 - INFO - Scheduler has been shut down
2023-10-13 00:06:30,312 - WARNING - Exiting immediately!
2023-10-13 00:07:34,065 - INFO - Bot démarré
2023-10-13 00:07:34,072 - INFO - Scheduler started
2023-10-13 00:07:37,932 - INFO - Utilisateur 1709873116 n'est pas dans la liste des bannis.
2023-10-13 00:07:37,933 - INFO - Utilisateur 1709873116 autorisé.
2023-10-13 00:10:07,281 - INFO - Received signal 2 (SIGINT), stopping...
2023-10-13 00:10:07,329 - INFO - Scheduler has been shut down
2023-10-13 00:10:07,414 - WARNING - Exiting immediately!
2023-10-13 00:16:35,654 - INFO - Scheduler started
2023-10-13 00:16:35,923 - INFO - Utilisateur 1709873116 n'est pas dans la liste des bannis.
2023-10-13 00:16:35,941 - INFO - Utilisateur 1709873116 autorisé.
2023-10-13 00:16:39,758 - WARNING - Utilisateur 1709873116 est dans la liste des bannis.
2023-10-13 00:16:39,766 - WARNING - Utilisateur 1709873116 est banni.
